Workbook

Sheet Summary
A1: mutinyhq.com page audit, Oct 28 2026
A2: One row per URL on the Pages tab. Edit Owner and Status (dropdown) there; counts below update from it.
A4: Action | B4: P1 | C4: P2 | D4: P3 | E4: Total | F4: Done
A5: redirect | B5: =COUNTIFS(Pages!$D$2:$D$251,$A5,Pages!$C$2:$C$251,"P1") -> 25 | C5: =COUNTIFS(Pages!$D$2:$D$251,$A5,Pages!$C$2:$C$251,"P2") -> 7 | D5: =COUNTIFS(Pages!$D$2:$D$251,$A5,Pages!$C$2:$C$251,"P3") -> 2 | E5: =SUM(B5:D5) -> 34 | F5: =COUNTIFS(Pages!$D$2:$D$251,$A5,Pages!$X$2:$X$251,"Done") -> 0
A6: remove | B6: =COUNTIFS(Pages!$D$2:$D$251,$A6,Pages!$C$2:$C$251,"P1") -> 0 | C6: =COUNTIFS(Pages!$D$2:$D$251,$A6,Pages!$C$2:$C$251,"P2") -> 0 | D6: =COUNTIFS(Pages!$D$2:$D$251,$A6,Pages!$C$2:$C$251,"P3") -> 1 | E6: =SUM(B6:D6) -> 1 | F6: =COUNTIFS(Pages!$D$2:$D$251,$A6,Pages!$X$2:$X$251,"Done") -> 0
A7: noindex | B7: =COUNTIFS(Pages!$D$2:$D$251,$A7,Pages!$C$2:$C$251,"P1") -> 16 | C7: =COUNTIFS(Pages!$D$2:$D$251,$A7,Pages!$C$2:$C$251,"P2") -> 1 | D7: =COUNTIFS(Pages!$D$2:$D$251,$A7,Pages!$C$2:$C$251,"P3") -> 4 | E7: =SUM(B7:D7) -> 21 | F7: =COUNTIFS(Pages!$D$2:$D$251,$A7,Pages!$X$2:$X$251,"Done") -> 0
A8: rewrite | B8: =COUNTIFS(Pages!$D$2:$D$251,$A8,Pages!$C$2:$C$251,"P1") -> 18 | C8: =COUNTIFS(Pages!$D$2:$D$251,$A8,Pages!$C$2:$C$251,"P2") -> 4 | D8: =COUNTIFS(Pages!$D$2:$D$251,$A8,Pages!$C$2:$C$251,"P3") -> 0 | E8: =SUM(B8:D8) -> 22 | F8: =COUNTIFS(Pages!$D$2:$D$251,$A8,Pages!$X$2:$X$251,"Done") -> 0
A9: fix | B9: =COUNTIFS(Pages!$D$2:$D$251,$A9,Pages!$C$2:$C$251,"P1") -> 83 | C9: =COUNTIFS(Pages!$D$2:$D$251,$A9,Pages!$C$2:$C$251,"P2") -> 61 | D9: =COUNTIFS(Pages!$D$2:$D$251,$A9,Pages!$C$2:$C$251,"P3") -> 15 | E9: =SUM(B9:D9) -> 159 | F9: =COUNTIFS(Pages!$D$2:$D$251,$A9,Pages!$X$2:$X$251,"Done") -> 0
A10: keep | B10: =COUNTIFS(Pages!$D$2:$D$251,$A10,Pages!$C$2:$C$251,"P1") -> 0 | C10: =COUNTIFS(Pages!$D$2:$D$251,$A10,Pages!$C$2:$C$251,"P2") -> 0 | D10: =COUNTIFS(Pages!$D$2:$D$251,$A10,Pages!$C$2:$C$251,"P3") -> 13 | E10: =SUM(B10:D10) -> 13 | F10: =COUNTIFS(Pages!$D$2:$D$251,$A10,Pages!$X$2:$X$251,"Done") -> 0
A11: Total | B11: =SUM(B5:B10) -> 142 | C11: =SUM(C5:C10) -> 73 | D11: =SUM(D5:D10) -> 35 | E11: =SUM(E5:E10) -> 250 | F11: =SUM(F5:F10) -> 0
A13: Positioning | B13: Pages
A14: current | B14: =COUNTIF(Pages!$E$2:$E$251,A14) -> 121
A15: mixed | B15: =COUNTIF(Pages!$E$2:$E$251,A15) -> 54
A16: legacy | B16: =COUNTIF(Pages!$E$2:$E$251,A16) -> 45
A17: neutral | B17: =COUNTIF(Pages!$E$2:$E$251,A17) -> 30
A19: Average AEO score | B19: =ROUND(AVERAGE(Pages!$F$2:$F$251),1) -> 3.7
A21: Legend: Priority P1 = untrue/conflicting facts, legacy CRO framing, or a high-value page with weak AEO; P2 = solid page missing AEO structure; P3 = minor. AEO score and persona fit are audit judgments. Truth baseline: /pricing, homepage and /enterprise as of Oct 28 2026.
A22: Example: /products/notetaker · P1 · rewrite · fix = question H1 "What is the best AI notetaker for sales calls?" + 40-60 word answer + vs Gong/Fireflies/Avoma section.
A24: Peec topic key | B24: Topic | C24: Mutiny / leader share of AI answers, Oct 28 2026
A25: SE | B25: Sales Enablement | C25: 3.7% / Seismic 61%
A26: DSR | B26: Digital Sales Rooms | C26: 1.3% / Aligned 38%
A27: SPP | B27: Sales Presentations and Proposals | C27: 2.9% / Qwilr 25%
A28: GTM | B28: AI GTM Stack | C28: 0.5% / Clay 47%
A29: CALL | B29: Sales Call Notes and Recording | C29: 1.0% / Gong 52%
A30: ASA | B30: AI Sales Assistants | C30: 0% / Gong 30%

Sheet Pages
A1: Path | B1: Type | C1: Priority | D1: Action | E1: Positioning | F1: AEO score (0-10) | G1: Peec topics (key on Summary tab) | H1: AE fit (0-3) | I1: Leader fit (0-3) | J1: H1 / title | K1: Issues found | L1: Recommended fix | M1: Legacy terms | N1: Date shown | O1: Question H1 | P1: Direct answer | Q1: FAQ block | R1: Sourced stats | S1: Fresh | T1: Internal links | U1: Unique meta | V1: In sitemap | W1: Owner | X1: Status | Y1: URL
A2: /product | B2: archive | C2: P1 | D2: redirect | E2: legacy | F2: 1 | H2: 0 | I2: 0 | J2: Bring your target accounts. We do the rest. (ABM/website platform; another fetch showed 'Scalable website personalization made easy') | K2: The whole page describes the retired CRO/website-personalization product and is live and crawlable at a generic URL (/product). This is the strongest on-site signal that Mutiny is a CRO/A-B testing tool • Testimonials attributed to customers (Amplitude, 6sense, Notion, ClickUp, Livestorm, Harness, Mode, Sprig, RStudio) are about website conversion, none in the current customer list; 'increasing conversion 95%' is unsourced • Claims 'GDPR, SOC2, and CCPA compliant' with legacy wording • CTAs point to a product tour and demo flow for the old product | L2: 301 /product to https://www.mutinyhq.com/ (or /products/automations) right away, remove it from any sitemap and request recrawl/removal in Search Console. Then sweep for other legacy URLs on this template (product tour, playbooks). | M2: Scalable website personalization made easy, no-code website personalization, B2B website personalization, Mutiny makes it easy to increase website conversions, Prove how personalization and A/B tests drive conversions and revenue, AI segmentation, Mutiny Visual Website Editor, Prove results with revenue attribution / Conversion reporting, Fast and flicker-free performance, dedicated personalization expert, Try winning website conversion strategies, Want to know how many leads your website loses? | O2: N | P2: N | Q2: N | R2: N | S2: N | T2: N | U2: N | V2: Y | X2: Not started | Y2: https://www.mutinyhq.com/product
A3: /blog/ab-testing-personalization-differences | B3: blog | C3: P1 | D3: redirect | E3: legacy | F3: 3 | H3: 0 | I3: 0 | J3: What's the difference between A/B Testing and Personalization? | K3: Unsourced stats: A/B win rate ~25% vs personalization ~75%; lift 3-5% vs 30-50% • Positions Mutiny as a website personalization tool (links /product) • CTA to legacy /playbooks 'conversion playbooks' • Clearbit referenced as standalone (now HubSpot) | L3: 301 to / (homepage). This is a textbook 'Mutiny = A/B testing + website personalization' page with a question H1 that AI engines can quote; do not refresh it. | M3: A/B testing, increase their website conversion rates, results ... in a matter of minutes using Mutiny – no engineering resources required, See how Brex, Notion, and Carta improved their conversion rates, Conversion Secrets | O3: Y | P3: N | Q3: N | R3: N | S3: N | T3: Y | U3: Y | V3: Y | X3: Not started | Y3: https://www.mutinyhq.com/blog/ab-testing-personalization-differences
A4: /blog/abm-tactics | B4: blog | C4: P1 | D4: redirect | E4: legacy | F4: 2 | H4: 0 | I4: 1 | J4: ABM Tactics: 6 Proven Tactic for Enterprise Marketing | K4: Title typo 'Tactic'; count mismatch (title 6, meta '5 ABM plays', intro '5 emerging tactics', list of 6) • Links legacy /use-cases/increase-website-conversion, /product, /integrations/6sense, /playbooks/snowflake-abm • 6sense quote on tests 'run in Mutiny' frames Mutiny as a testing tool | L4: 301 to /use-cases/account-based-marketing. Combines A/B testing, website conversion links and 'personalized digital asset' framing. | M4: experimentation and continuous optimization (links /use-cases/increase-website-conversion), A/B testing, use Mutiny to deliver the most relevant personalization for each account, website to become a personalized digital asset, personalized landing pages | O4: N | P4: N | Q4: N | R4: N | S4: N | T4: Y | U4: N | V4: Y | X4: Not started | Y4: https://www.mutinyhq.com/blog/abm-tactics
A5: /blog/account-based-marketing-personalization | B5: blog | C5: P1 | D5: redirect | E5: legacy | F5: 3 | H5: 0 | I5: 0 | J5: Account-Based Marketing Personalization: The Key to Scale | K5: Meta description ~600 chars (truncated in search) • 'Mutiny's upcoming ad integration' is outdated • 'Our own data shows ... over 30% higher open rates' unsourced • 'Mutiny doesn't send emails directly' is a stale product claim • Account Studio is a legacy product name | L5: 301 to /use-cases/account-based-marketing. The lead tactic is 'website and landing page personalization' with Mutiny as the platform. | M5: Website and landing page personalization, Mutiny empowers teams to build bespoke, high-performance landing pages, Conversion optimization, dynamically insert social proof ... based on industry, persona, AI-driven personalization platform | O5: N | P5: N | Q5: N | R5: Y | S5: N | T5: Y | U5: N | V5: Y | X5: Not started | Y5: https://www.mutinyhq.com/blog/account-based-marketing-personalization
A6: /blog/ai-gtm | B6: blog | C6: P1 | D6: redirect | E6: legacy | F6: 2 | H6: 0 | I6: 0 | J6: How AI Is Revolutionizing Go-To-Market Strategies | K6: Unsourced '150 million people' and 'converting 70% more customers' • Links legacy /product/audience-segmentation, /product/conversion-reporting, /community/apply (M2) • Describes Mutiny as a website personalization platform | L6: 301 to /blog/how-are-b2b-sales-teams-using-ai-in-2026. The 'ai-gtm' slug is valuable, so a rewrite in place as 'What is an AI GTM stack?' for the AI GTM Stack topic is also an option. | M6: plugs into ... your website to identify who's on your site, Over 150 million people have actually seen an experience Mutiny has personalized on the web, recommends which pages to personalize, enabling A/B testing, multiple variations of a homepage | O6: N | P6: N | Q6: N | R6: N | S6: N | T6: Y | U6: Y | V6: Y | X6: Not started | Y6: https://www.mutinyhq.com/blog/ai-gtm
A7: /blog/ai-marketing | B7: blog | C7: P1 | D7: redirect | E7: legacy | F7: 2 | H7: 0 | I7: 0 | J7: The impact of AI on the next era of growth marketing | K7: Typo 'GTP-3' • Legacy CRO case (ClickUp 850% testing velocity, 1,600 experiences) • Intellipse acquisition and community playbooks are legacy • Links /product/website-personalization, /product/audience-segmentation, /product/conversion-reporting | L7: 301 to /blog (or noindex). It is a history of Mutiny's old CRO AI with nothing reusable for current topics. | M7: growth experimentation, no-code tool that allows marketing teams to unlock their growth, recommended conversion opportunities, website personalization, high-converting website copy, the art and science of conversion | O7: N | P7: N | Q7: N | R7: N | S7: N | T7: Y | U7: Y | V7: Y | X7: Not started | Y7: https://www.mutinyhq.com/blog/ai-marketing
A8: /blog/high-conversion-landing-page-mistakes-to-avoid | B8: blog | C8: P1 | D8: redirect | E8: legacy | F8: 2 | H8: 0 | I8: 0 | J8: Conversion Myths Debunked: Three Landing Page Mistakes To Avoid | K8: Pure CRO content (Spiralyze agency); test-result images missing ('Here are the real results:' is followed by nothing) • Attentive 77% and Notion 60% conversion lifts link to legacy /playbooks • Typo 'Mutliply' • Links /blog/website-personalization-framework, /blog/how-to-invest-in-conversion-for-b2b-the-second-lever | L8: 301 to / (or /blog). Pure CRO content, and the A/B testing post links to it. | M8: Conversion Rate Optimization, high conversion landing pages, experiment velocity, statistical significance, optimizing the conversion landing pages | O8: N | P8: N | Q8: N | R8: N | S8: N | T8: Y | U8: Y | V8: Y | X8: Not started | Y8: https://www.mutinyhq.com/blog/high-conversion-landing-page-mistakes-to-avoid
A9: /blog/how-to-build-a-revenue-generating-abm-program | B9: blog | C9: P1 | D9: redirect | E9: legacy | F9: 3 | H9: 0 | I9: 1 | J9: How To Build a Revenue Generating ABM program | K9: Describes Mutiny's own ICP and product as website/marketing personalization • '97 percent of marketers' stat is from 2018 • Outdated vendors: DiscoverOrg (now ZoomInfo), Clearbit (now HubSpot), apollohq.com • Typo 'Net Performer Score' (Net Promoter) • Unsourced '7-8% of target accounts book a demo ... 3x the industry standard' • Charts and email examples referenced but missing • Legacy playbook stats (6sense 442%, Brex 60%) | L9: 301 to /use-cases/account-based-marketing, and update the ABM posts that link here (abm-software, enterprise-account-based-marketing, account-based-marketing-personalization). | M9: We use our software to create personalized landing pages (links /use-cases/increase-website-conversion), they still have a big need for personalization, advice ... on how to improve their marketing personalization, companies wanting to do personalization purely for social ads | O9: Y | P9: N | Q9: N | R9: N | S9: N | T9: Y | U9: Y | V9: Y | X9: Not started | Y9: https://www.mutinyhq.com/blog/how-to-build-a-revenue-generating-abm-program
A10: /blog/how-to-get-sdr-adoption-for-mutiny-campaigns | B10: blog | C10: P1 | D10: redirect | E10: legacy | F10: 2 | H10: 1 | I10: 1 | J10: How to Get SDR Adoption for Mutiny Campaigns | K10: Opening sentence and meta define Mutiny as a website personalization platform with an experience editor (old product) • Unsourced customer stats: Brex, Mode, Radar '10X higher email responses and book 3X more meetings' • 'Set up alerts in Mutiny' refers to legacy feature • Step 3 heading is a self-anchor link (#step_3) • Meta truncated with '...'; byline 'Mutiny Team', no date | L10: 301 to /use-cases/account-executives (or /blueprints/cold-outreach). The first sentence and meta tell AI engines Mutiny is a website personalization platform, which is the CRO framing to retire. | M10: personalize your website for target accounts, Mutiny's experience editor, 1:1 personalized landing pages, measure results with an AB test, ABM teams work with SDRs | O10: Y | P10: N | Q10: N | R10: N | S10: N | T10: N | U10: N | V10: Y | X10: Not started | Y10: https://www.mutinyhq.com/blog/how-to-get-sdr-adoption-for-mutiny-campaigns
A11: /blog/landing-page-personalization | B11: blog | C11: P1 | D11: redirect | E11: legacy | F11: 2 | H11: 1 | I11: 0 | J11: 7 Landing Page Personalizations Proven To Close ABM Deals | K11: Links to dead legacy URLs /product/abm-campaigns, /product, /integrations, /playbooks, /academy • Outbound link to a competitor list (gokickflip.com/blog/personalization-software) • Meta says microsite, title says landing page • Example screenshots missing; no date | L11: 301 to /blueprints/1-1-abm (closest current asset) or /use-cases/account-based-marketing. If it stays live for any time, remove the competitor outbound link. | M11: Your website should be more than just a digital brochure, tailoring your site to speak directly to individual companies, make your website work harder, Personalization isn’t about making your website flashy, landing page personalization | O11: N | P11: N | Q11: N | R11: N | S11: N | T11: N | U11: N | V11: Y | X11: Not started | Y11: https://www.mutinyhq.com/blog/landing-page-personalization
A12: /blog/marketing-messaging-framework | B12: blog | C12: P1 | D12: redirect | E12: legacy | F12: 1 | H12: 0 | I12: 1 | J12: The marketing messaging framework used to deeply understand your ICP | K12: Typos: 'focus on on going after', 'Spices framework', 'Why this this insight' • Links /blog/the-second-lever-takeaways and in-page anchors (#recording, #CRM) that do not resolve; workshop video missing • Framework image and example spreadsheet referenced but not shown • Meta truncated | L12: 301 to /blog (or noindex). Its 'mine your call recordings for messaging' section could seed a new CALL-topic post such as 'How do you turn sales call recordings into messaging insights?' built around Mutiny's notetaker. | M12: conversion rate optimization agency Speero, increase conversion rates across your website, our conversion rate experiments, website personalization using Mutiny, web experiments | O12: N | P12: N | Q12: N | R12: N | S12: N | T12: N | U12: N | V12: Y | X12: Not started | Y12: https://www.mutinyhq.com/blog/marketing-messaging-framework
A13: /blog/mutiny-6sense-integration | B13: blog | C13: P1 | D13: redirect | E13: legacy | F13: 1 | H13: 0 | I13: 0 | J13: Announcing Mutiny’s integration with 6sense | K13: 6sense website integration listed as legacy in truth.md • Stats: 6sense 123% conversion uplift, Qualtrics +40% identified visitors (legacy product results) • CTA /request-invite (old) • Meta truncated | L13: 301 to /products/integration. This page is a direct 'Mutiny = website personalization + 6sense' signal that AI engines repeat. | M13: serve highly personalized website experiences, more conversions and higher ROI, 123% conversion rate uplift, different versions of our website, ROI report for your website, playbooks for increasing conversion | O13: N | P13: N | Q13: N | R13: N | S13: N | T13: N | U13: N | V13: Y | X13: Not started | Y13: https://www.mutinyhq.com/blog/mutiny-6sense-integration
... A24: /blog/unlocking-more-mqls | B24: blog | C24: P1 | D24: redirect | E24: legacy | F24: 0 | H24: 0 | I24: 0 | J24: Unlocking More MQLs With Personalized Advertising Landing Pages | K24: Describes the retired web-personalization product (segments on UTMs, full-site personalization) • Meta description is a truncated first sentence • Links old ga-dev-tools URL builder • No date; author 'Mutiny Team' | L24: 301 to /blog. Pure legacy CRO/MQL/landing-page personalization how-to with no current equivalent. | M24: Unlocking More MQLs, landing page personalization, full-site personalization, define your segment ... UTM parameters, personalized pages | O24: N | P24: N | Q24: N | R24: N | S24: N | T24: N | U24: N | V24: Y | X24: Not started | Y24: https://www.mutinyhq.com/blog/unlocking-more-mqls
A25: /products/sales-enablement | B25: product | C25: P1 | D25: redirect | E25: current | F25: 3 | G25: SE (Sales Enablement) | H25: 1 | I25: 3 | J25: No real H1; main heading is H2 'Sales content that moves deals forward'. The mock UI renders '# Library' and '# Usage' as H1s | K25: Title and meta are copied from /products/automations, so 'sales enablement' appears in neither • Near-duplicate of /use-cases/sales-enablement (same H1, same sections) • Bottom CTA 'Start for free' links to /talk-to-sales • Mock UI headings 'Library' and 'Usage' render as H1s • Mock library item 'Website visitor analytics demo' hints at the legacy product | L25: 301 to https://www.mutinyhq.com/use-cases/sales-enablement after moving its FAQ and usage-dashboard section there, so there is one canonical sales-enablement page for the SE topic (Mutiny 3.7% vs Seismic 61%). | O25: N | P25: N | Q25: Y | R25: N | S25: N | T25: N | U25: N | V25: Y | X25: Not started | Y25: https://www.mutinyhq.com/products/sales-enablement
A26: /use-cases/increase-website-conversion | B26: use-case | C26: P1 | D26: redirect | E26: legacy | F26: 0 | H26: 0 | I26: 0 | J26: 1:1 web personalization without engineers | K26: Live legacy CRO page, not in sitemap; linked 5x from /blog/scaling-abm-strategy and from snowflake-abm-tech-stack. | L26: 301 to /use-cases/account-based-marketing (or /), fix the inbound links, request recrawl. | V26: N | X26: Not started | Y26: https://www.mutinyhq.com/use-cases/increase-website-conversion
A27: /blog/abm-question-answer-snowflake | B27: blog | C27: P1 | D27: noindex | E27: legacy | F27: 3 | H27: 0 | I27: 1 | J27: 5 ABM Questions You've Always Wanted To Ask, Answered By Snowflake's ABM Team | K27: Links legacy pages /product/audience-segmentation, /use-cases/abm-campaigns, /academy/abm-mba • Ties Snowflake (flagship customer) to website personalization; current Snowflake proof is Hillary Carpio on rep-generated content • Typo 'wholistic' | L27: Noindex (or 301 to /customers). It teaches engines that Snowflake uses Mutiny for website personalization, which conflicts with the current Snowflake quote about reps generating deal content. | M27: use Mutiny to deliver the most relevant personalization for each account, using AI to optimize landing page content, 1:1 personalized microsites ... dynamically updated, 6sense delivers a cohesive and relevant website experience | O27: N | P27: N | Q27: Y | R27: N | S27: N | T27: Y | U27: Y | V27: Y | X27: Not started | Y27: https://www.mutinyhq.com/blog/abm-question-answer-snowflake
A28: /blog/cmo-profitable-growth | B28: blog | C28: P1 | D28: noindex | E28: legacy | F28: 2 | H28: 0 | I28: 1 | J28: The CMOs guide to profitable growth | K28: Describes Mutiny as automated website personalization (links /product) • '$19 out of every $20' wasted, from a 2019 WordStream benchmark • Typo 'ORK' (OKR); 'CMOs guide' missing apostrophe • Charts and dashboards referenced but missing • Clearbit listed as standalone (now HubSpot) | L28: Noindex. If you keep Jaleh's Gusto story, delete the 'we decided to build Mutiny' website-personalization paragraph and the 'use technology to enable conversion' takeaway. | M28: Invest in conversion, not just demand, create personalized website experiences for every visitor, we decided to build Mutiny – a platform that does this automatically, power personalization and conversion, Use technology to enable conversion | O28: N | P28: N | Q28: N | R28: Y | S28: N | T28: Y | U28: Y | V28: Y | X28: Not started | Y28: https://www.mutinyhq.com/blog/cmo-profitable-growth
A29: /blog/event-driven-cdn-caching | B29: blog | C29: P1 | D29: noindex | E29: legacy | F29: 1 | H29: 0 | I29: 0 | J29: Event Driven CDN Caching | K29: Meta description and first sentence define Mutiny as 'a no-code conversion platform', an explicitly banned legacy descriptor • 100M requests/month and 50M events/day are dated and unsourced • Careers link to apply.workable.com/mutiny may be stale | L29: Noindex this engineering post about the retired web-personalization stack. At minimum, rewrite the meta and opening line to remove 'no-code conversion platform'. | M29: no-code conversion platform, personalize their customer journey, real-time decisions about what a user should see on customer websites, great personalization product | O29: N | P29: N | Q29: N | R29: N | S29: N | T29: N | U29: N | V29: Y | X29: Not started | Y29: https://www.mutinyhq.com/blog/event-driven-cdn-caching
A30: /blog/flint-alternatives-8-ai-website-and-landing-page-platforms-b2b-teams-evaluate-in-2026 | B30: blog | C30: P1 | D30: noindex | E30: legacy | F30: 5 | H30: 0 | I30: 1 | J30: Flint alternatives: 8 AI website and landing page platforms B2B teams evaluate in 2026 | K30: Puts Mutiny in the AI website/landing-page optimization category alongside Optimizely, Intellimize and Unbounce (CRO framing) • Intellimize was acquired by Webflow in 2024 but is listed as independent • Enterprise '~$30K+' (pricing page: $40k) • Flint and Tofu funding claims unsourced • No date; meta has no answer | L30: Noindex or remove. A fresh, AEO-structured 2026 page telling engines Mutiny is an alternative to Optimizely/Intellimize/Unbounce directly feeds the CRO misclassification. If deleting, 301 to /blog/highspot-alternatives-8-platforms-b2b-teams-evaluate-in-2026. | M30: AI website and landing page platforms, personalized web experiences, Optimizely ... A/B testing, multivariate testing, and personalization, Often included on Mutiny and Flint alternatives lists (Intellimize), dynamic personalization (BMC quote) | O30: Y | P30: Y | Q30: Y | R30: N | S30: N | T30: Y | U30: N | V30: Y | X30: Not started | Y30: https://www.mutinyhq.com/blog/flint-alternatives-8-ai-website-and-landing-page-platforms-b2b-teams-evaluate-in-2026
A31: /blog/intellipse-ai-acquisition | B31: blog | C31: P1 | D31: noindex | E31: legacy | F31: 1 | H31: 0 | I31: 1 | J31: Mutiny acquires Intellipse to accelerate AI roadmap | K31: Unsourced stats: 143% more tests, 88% more conversions, 500,000 web pages, 100M+ people across 4M+ companies, CTA change +28%, ~70% of visitors identified • '$19 out of $20' wasted-spend stat • Mentions GPT-3 and 'the recession' (outdated) • Links to dead legacy pages /product/audience-segmentation, /use-cases/increase-website-conversion, /product/website-personalization, /product/conversion-reporting, /careers | L31: Noindex (or 301 to /blog/introducing-the-new-mutiny). Every section describes Mutiny as website A/B testing and conversion optimization; if kept for history, add a top editor's note that Mutiny is now the sales assistant and cut the product description. | M31: serve different versions to buyers, 1M+ permutations for site optimization, launch 143% more tests and see 88% more conversions, transformed conversion from a niche A/B testing tool, copy that converts, conversion marketing | O31: N | P31: N | Q31: N | R31: N | S31: N | T31: N | U31: N | V31: Y | X31: Not started | Y31: https://www.mutinyhq.com/blog/intellipse-ai-acquisition
A32: /blog/introducing-campaigns | B32: blog | C32: P1 | D32: noindex | E32: mixed | F32: 1 | H32: 1 | I32: 1 | J32: Introducing Campaigns: Reimagining the enterprise buying experience | K32: Unsourced stats: outbound effectiveness down 71%, 89% of buyers turn to AI, 65% less likely to purchase • CTA 'Book a demo' to /get-started and 'contact your Growth Strategist' (old flow) • Campaigns, sidepop and web extension are not the current product • No date | L32: Noindex or 301 to /blog/introducing-the-new-mutiny; the product it launches is retired. Do not reuse the 71/89/65% stats anywhere without a source. | M32: website sidepop, Scalable personalization with microsites, session replays and account intelligence, web extension, Marketing win stories | O32: N | P32: N | Q32: N | R32: N | S32: N | T32: N | U32: N | V32: Y | X32: Not started | Y32: https://www.mutinyhq.com/blog/introducing-campaigns
A33: /blog/mutiny-product-release-september-2022 | B33: blog | C33: P1 | D33: noindex | E33: legacy | F33: 0 | H33: 0 | I33: 0 | J33: The Raccoon Round Up: September 2022 | K33: Meta claims 'Everything you’ll see today is currently available in Mutiny' (false now) • Links to support.mutinyhq.com articles and a google.com redirect URL • Release notes for the retired website-experience product | L33: Noindex or 410. Pure 2022 release notes for the retired website editor; no search or AI value and the meta asserts the features are still available. | M33: Visual Editor, Mutiny experience or campaign, segments and pages, Custom JS, Maintenance Recommendations, personalization strategy | N33: September 2022 (in title) | O33: N | P33: N | Q33: N | R33: N | S33: N | T33: N | U33: N | V33: Y | X33: Not started | Y33: https://www.mutinyhq.com/blog/mutiny-product-release-september-2022
A34: /blog/mutiny-raises-50m-series-b-to-help-companies-turn-wasted-marketing-spend-into-revenue | B34: blog | C34: P1 | D34: noindex | E34: legacy | F34: 1 | H34: 0 | I34: 1 | J34: Mutiny Raises $50M Series B to Help Companies Turn Wasted Marketing Spend Into Revenue | K34: Title uses the exact legacy phrase 'turn wasted marketing spend into revenue' • Links TechCrunch headline 'Mutiny, which personalizes website copy and headlines using AI' • '$19 out of every $20' wasted stat sourced to a third-party conversion benchmark • No date; no note that total funding is now $72M or that the product changed • Meta truncated | L34: Noindex and add a top editor's note ('Mutiny has since rebuilt as the sales assistant for customer-facing work; total funding $72M') linking to /llm-info. Keep investor and funding facts on /llm-info so AI still learns them. | M34: Turn Wasted Marketing Spend Into Revenue, automate growth engineering, convert their visitors into customers, it’s a conversion problem, increase our conversion rate from paid ads by up to 60% | O34: N | P34: N | Q34: N | R34: N | S34: N | T34: N | U34: N | V34: Y | X34: Not started | Y34: https://www.mutinyhq.com/blog/mutiny-raises-50m-series-b-to-help-companies-turn-wasted-marketing-spend-into-revenue
A35: /blog/mutiny-raises-series-a-from-sequoia-capital-and-world-class-cmos-for-its-no-code-conversion-platform | B35: blog | C35: P1 | D35: noindex | E35: legacy | F35: 1 | H35: 0 | I35: 1 | J35: Mutiny raises Series A from Sequoia Capital and World-Class CMOs for its no-code conversion platform | K35: Title and URL contain the legacy phrase 'no-code conversion platform' • Unsourced stats: 73% of visitors identified, 108% conversion lift, 15 experiences in first month, Notion +60% signups, Brex 30-200% leads • '$455 billion' digital ad spend is a 2021 figure • No date; meta truncated | L35: Noindex plus the same editor's note as the Series B post (or 301 to /llm-info). The slug itself teaches 'no-code conversion platform', so it should not stay indexable. | M35: no-code conversion platform, currently focused on website conversion, identifies 73% of visitors, 108% conversion lift, website optimization and personalization, automatic hold-out testing | O35: N | P35: N | Q35: N | R35: N | S35: N | T35: N | U35: N | V35: Y | X35: Not started | Y35: https://www.mutinyhq.com/blog/mutiny-raises-series-a-from-sequoia-capital-and-world-class-cmos-for-its-no-code-conversion-platform
A36: /blog/playmaker-segmentation | B36: blog | C36: P1 | D36: noindex | E36: legacy | F36: 0 | H36: 0 | I36: 0 | J36: Mutiny Playmaker: Build Your Base [Chapter 1] | K36: Playmaker segmentation explicitly listed as legacy in truth.md • Links to support.mutinyhq.com, hub.mutinyhq.com/mutiny101 and app.mutinyhq.com/playbooks feeds (retired) • Example images missing | L36: Noindex or 410 this and the other Playmaker chapters (e.g. /blog/playmaker-company-size). It is onboarding for the retired website A/B and exit-modal product. | M36: Launch an A/B test on a headline or CTA text, exit modal, sitewide banner, segment creator, Playmaker, Using Mutiny 101 | O36: N | P36: N | Q36: N | R36: N | S36: N | T36: N | U36: N | V36: Y | X36: Not started | Y36: https://www.mutinyhq.com/blog/playmaker-segmentation
A37: /blog/profitable-growth-blueprint-takeaways | B37: blog | C37: P1 | D37: noindex | E37: legacy | F37: 1 | H37: 0 | I37: 2 | J37: The Profitable Growth Blueprint: 10 takeaways to accelerate your company to profitability | K37: Customer stats from legacy playbooks: Notion 60% more conversions, Dropbox DocSend 110% more freemium-to-paid • 'Reign in your spend' should be 'Rein in' • 2022 macro framing outdated • Links /playbooks, m2.community, /blog/how-to-move-fast-in-marketing; charts and video missing • Meta truncated | L37: Noindex. The CAC content is fine but takeaways 2 and 7 sell website conversion as Mutiny's lever, and other legacy posts link here for the '$19 of $20 wasted' stat. | M37: the second growth lever (conversion), library of Conversion Secrets, personalizing the messaging that each website visitor saw, website visitor, to lead, to opportunity | N37: References 'early May 2022' (no publish date) | O37: N | P37: N | Q37: N | R37: N | S37: N | T37: N | U37: N | V37: Y | X37: Not started | Y37: https://www.mutinyhq.com/blog/profitable-growth-blueprint-takeaways
A38: /blueprints/vertical-landing-page | B38: blueprint | C38: P1 | D38: noindex | E38: legacy | F38: 4 | H38: 0 | I38: 0 | J38: Vertical Landing Page | K38: FAQ: Enterprise 'starting at $30k' conflicts with /pricing • Whole page reads as landing-page/CRO optimization for marketers, the framing /llm-info says not to use • Descriptor 'GTM agent...'; unsourced 4.5x/100% stat • Title 'Mutiny'; generic meta | L38: Noindex and drop from the sitewide Prospect footer column, since it reinforces the CRO/landing-page story Matt flagged as the #1 risk. If it must stay indexed, rewrite as an industry one-pager reps send to a vertical account list, with no paid-traffic conversion framing. | M38: 'conversion-focused landing page', 'Paid search and social campaigns', Unbounce landing page conversion benchmarks, 'message match between the ad and the page headline', BMC quote: 'dynamic personalization' | N38: July 15, 2026 | O38: N | P38: Y | Q38: Y | R38: Y | S38: N | T38: Y | U38: N | V38: Y | X38: Not started | Y38: https://www.mutinyhq.com/blueprints/vertical-landing-page
A39: /case-studies/andela | B39: case-study | C39: P1 | D39: noindex | E39: legacy | F39: 2 | H39: 0 | I39: 1 | J39: How Andela 14X'd Enterprise Opportunities with Hyper-Personalized Experiences | K39: Story is the legacy website-personalization/ABM product (web visitor pop-ups, industry personalization), told by a Senior ABM Manager • Links to /product/abm-campaigns (returns empty, likely 404), /product and /blog/landing-page-personalization (legacy) • Mixes 'ABX' and 'ABM' for the same program • 2.1x engagement and 14x opportunities have no stated baseline or time window ('About a few months after launch') • No H1 (title repeated 3x as H2); meta is 'Andela, Ashley Rendall' | L39: Noindex (and remove from /customers) because it documents the legacy website-personalization product. If Andela now uses the sales assistant, replace with a new story; otherwise keep only as an unlisted reference. | M39: 'Hyper-Personalized Experiences', 'personalized experiences by industries', 'smart pop-ups that recognized when visitors from target accounts were on their website', 'microsites with multiple layers of personalization', 'Visitor's company name' in hero | O39: N | P39: N | Q39: N | R39: N | S39: N | T39: N | U39: N | V39: Y | X39: Not started | Y39: https://www.mutinyhq.com/case-studies/andela
A40: /case-studies/launchdarkly | B40: case-study | C40: P1 | D40: noindex | E40: legacy | F40: 2 | H40: 0 | I40: 1 | J40: Scaling Process, Scaling Impact: LaunchDarkly Achieves 150 % of Meeting Targets in Under 60 Days | K40: Documents the legacy website-personalization/ABM product (Campaigns, sidepop, web-visitor alerts) by a solo ABM marketer • Links to /product (returns empty, likely 404) • Title spacing typo '150 %' • Undated ('in Q1') so readers cannot tell the year • No H1; meta 'LaunchDarkly, Colleen Pierre' | L40: Noindex and remove from /customers: it is the old Campaigns/web-visitor product and feeds the CRO framing AI engines repeat. Replace with a current sales-assistant story if LaunchDarkly is still a customer. | M40: 'Mutiny's AI-native product, Campaigns', 'Campaigns sidepop to target known visitors', 'web extension... alerts when target accounts visit the site', 'Account Intelligence tool', 'dynamically added company names into the header' | O40: N | P40: N | Q40: N | R40: Y | S40: N | T40: N | U40: N | V40: Y | X40: Not started | Y40: https://www.mutinyhq.com/case-studies/launchdarkly
A41: /case-studies/simpro | B41: case-study | C41: P1 | D41: noindex | E41: legacy | F41: 2 | H41: 0 | I41: 1 | J41: How Simpro Scaled Personalization and Influenced $640K ARR with Mutiny | K41: Pure website-personalization/CRO story (experiments, web journeys, demo-request conversion lift) • Meta credits 'Tim Lamb' but the only quote is from Sara Cooper • '$640K in incremental ARR influenced' mixes incremental and influenced attribution • 2024 data with no date shown • No H1 | L41: Noindex and remove from /customers; it is the clearest CRO/web-personalization proof point on the site. If kept unlisted, fix the Tim Lamb vs Sara Cooper attribution and the 'incremental ARR influenced' wording. | M41: 'Scaled Personalization', 'shifting from generic web experiences to data-driven personalization', 'ran a wave of experiments', '142% increase in demo request conversions', 'competitor intent audiences', 'Director of Web Strategy' | O41: N | P41: N | Q41: N | R41: N | S41: N | T41: N | U41: N | V41: Y | X41: Not started | Y41: https://www.mutinyhq.com/case-studies/simpro
A42: /faqs/what-is-replacing-traditional-abm-tools-in-modern-gtm-stacks | B42: faq | C42: P1 | D42: noindex | E42: legacy | F42: 3 | H42: 0 | I42: 1 | J42: What is replacing traditional ABM tools in modern GTM stacks? | K42: Puts Mutiny in the same sentence and category as 'website personalization', Matt's #1 AEO risk • Unsourced: 'Mutiny anchors this category' • Unsourced: 'Most teams that make the move see... lower tool count and higher personalization volume' • Also-asked 'How does Mutiny compare to Highspot?' is off-topic; old footer slugs (known); CTA goes to the homepage | L42: Noindex, or rewrite without any 'website personalization' wording. If rewritten, open with: 'Sales teams are replacing ABM page tools with a sales assistant that builds deal assets from every call; Mutiny is the sales assistant built for customer-facing work.' | M42: website personalization and landing-page swaps, Mutiny anchors this category, Legacy ABM personalization... website personalization, middle-of-funnel acquisition, extends ABM past landing pages | O42: Y | P42: Y | Q42: Y | R42: N | S42: N | T42: N | U42: N | V42: Y | X42: Not started | Y42: https://www.mutinyhq.com/faqs/what-is-replacing-traditional-abm-tools-in-modern-gtm-stacks
A43: /automation/meeting-follow-up | B43: automation | C43: P1 | D43: rewrite | E43: current | F43: 2 | G43: CALL (Sales Call Notes and Recording), ASA (AI Sales Assistants) | H43: 3 | I43: 2 | J43: Never drop a follow-up again | K43: Typo in the lead sentence, rendered twice: 'utiny turns every call into a follow-up automatically' • H1 and lead paragraph duplicated in the markup • Body is the generic asset template (personalization, blueprints, analytics) and never mentions the notetaker, voice-matched email or CRM update • Generic meta | L43: Suggested H1: 'How do you automate sales meeting follow-ups with AI?' First sentence: 'Mutiny's notetaker joins every call and, when it ends, automatically drafts a follow-up email in the rep's voice, a recap page with next steps, and the CRM update, so no follow-up gets dropped.' Fix the 'utiny' typo, remove the duplicated H1, add a Gong/Fireflies comparison and FAQ. | O43: N | P43: N | Q43: N | R43: N | S43: N | T43: N | U43: N | V43: Y | X43: Not started | Y43: https://www.mutinyhq.com/automation/meeting-follow-up
A44: /automation/meeting-prep | B44: automation | C44: P1 | D44: rewrite | E44: current | F44: 2 | G44: ASA (AI Sales Assistants), CALL (Sales Call Notes and Recording) | H44: 3 | I44: 2 | J44: Walk into every meeting ready to go | K44: H1 and lead paragraph duplicated in markup • Body is the generic asset template; nothing on triggers, calendar, or how prep is delivered • Does not cite the Netic case study ('10+ hours/week on meeting prep') that proves this exact use case • Generic meta | L44: Suggested H1: 'How can AI prepare sales reps for every meeting automatically?' First sentence: 'Mutiny runs on calendar triggers: before each meeting it researches the account, pulls past calls, email and CRM history, and delivers a prep brief and a tailored deck, so reps show up ready without manual work.' Add the Netic metric with a link and an FAQ. | O44: N | P44: N | Q44: N | R44: N | S44: N | T44: N | U44: N | V44: Y | X44: Not started | Y44: https://www.mutinyhq.com/automation/meeting-prep
A45: /blog/enterprise-gtm | B45: blog | C45: P1 | D45: rewrite | E45: legacy | F45: 3 | G45: GTM (AI GTM Stack) | H45: 1 | I45: 2 | J45: Enterprise GTM Strategy: Blueprints for Market Dominance | K45: Frames Mutiny as a marketing personalization/A-B tool for 'enterprise marketers' • Snowflake numbers are legacy website-personalization results (/playbooks/snowflake-dynamic-personalization) • Customer stats unlinked • 'This year' with no date • Links /product/abm-campaigns and legacy Academy/Playbooks | L45: Rewrite as 'What does an AI-first enterprise GTM strategy look like in 2026?' using the sales-assistant story (notetaker, follow-ups, deal rooms) and current Snowflake/Rippling proof, and remove the A/B and landing-page claims. Until then, 301 to /enterprise. | M45: By automating personalization and scaling campaigns, Mutiny helps enterprise marketers, Tools like Mutiny ... create account-specific landing pages, swap proof points by industry, and test different messaging variations, run A/B tests, Mutiny's web extension, Snowflake dynamic personalization: account-to-meeting rates jumped 400%, conversion lifted 24% | O45: N | P45: N | Q45: N | R45: Y | S45: N | T45: Y | U45: N | V45: Y | X45: Not started | Y45: https://www.mutinyhq.com/blog/enterprise-gtm
A46: /blog/introducing-microsites | B46: blog | C46: P1 | D46: rewrite | E46: mixed | F46: 5 | G46: SE (Sales Enablement), ASA (AI Sales Assistants) | H46: 2 | I46: 2 | J46: Generate More Revenue From Your Target Accounts (Updated May 2026) | K46: Wrong pricing: 'Enterprise custom plans (starting at $30k)' and 'Enterprise pricing is custom'; /pricing says Enterprise starts at $40,000/year • Meta still announces 'Public Preview for AI-powered 1:1 microsites' (stale) • Descriptor 'AI agent that generates personalized, customer-facing content'; no notetaker/sales assistant story • ITSMA '2-3x higher engagement / <20% can run at scale' links to itsma.com homepage; Forrester '60-70% unused' links to forrester.com homepage • 'account executives' and 'sales leaders' links point to the homepage • Two H1s; slug introducing-microsites mismatches title • Vanta (Celeste Cote) not in named-customer list; verify | L46: Fix the $30k Enterprise price to $40,000/year today. Rewrite as 'What is Mutiny? The AI sales assistant for customer-facing work' (or 301 to /enterprise), leading with notetaker and automatic follow-ups, with one H1, a new meta, real links to /use-cases/account-executives and /use-cases/sales-leaders, and the ITSMA/Forrester stats linked to actual reports. | M46: 1:1 microsites, ABM campaigns: personalized landing pages, microsites, ads, The previous version focused on website personalization for inbound traffic | N46: Updated May 2026 (in title) | O46: N | P46: Y | Q46: N | R46: N | S46: Y | T46: N | U46: N | V46: Y | X46: Not started | Y46: https://www.mutinyhq.com/blog/introducing-microsites
A47: /blog/userled-alternatives-8-abm-personalization-platforms-b2b-teams-evaluate-in-2026 | B47: blog | C47: P1 | D47: rewrite | E47: legacy | F47: 4 | H47: 1 | I47: 1 | J47: Userled alternatives: 8 ABM personalization platforms B2B teams evaluate in 2026 | K47: Recommends Mutiny for landing-page optimization and web personalization (exact legacy CRO framing) • Pricing wrong: 'Enterprise (~$30K+)' • Unsupported: 'Mutiny has the leading AI design capability in the market' • Unsourced competitor claims (Userled 'primarily marketing-operated', '2026 Startups 100') • Generic meta description; no internal links in body | L47: Delete the 'landing-page optimization' and 'web personalization' recommendations and retitle away from 'ABM personalization platforms' (e.g. 'What are the best Userled alternatives for sales teams?'), positioning Mutiny as the sales assistant. If no rewrite capacity, noindex it. | M47: ABM personalization platforms, 'Our focus is paid acquisition and landing-page optimization at scale' -> Look at Mutiny or Flint, 'We want web personalization and ABM orchestration' -> Look at Mutiny, personalized web experiences, agentic personalization platforms | O47: Y | P47: Y | Q47: Y | R47: N | S47: N | T47: N | U47: N | V47: Y | X47: Not started | Y47: https://www.mutinyhq.com/blog/userled-alternatives-8-abm-personalization-platforms-b2b-teams-evaluate-in-2026
A48: /blog/what-is-agentic-ai-in-sales | B48: blog | C48: P1 | D48: rewrite | E48: mixed | F48: 5 | G48: ASA (AI Sales Assistants), GTM (AI GTM Stack) | H48: 1 | I48: 2 | J48: What is agentic AI in sales? | K48: 'Where does Mutiny fit' describes Mutiny as an ABM landing-page/microsite platform, contradicting the sales-assistant positioning • 'The category emerged in late 2025' unsourced • No FAQ block, no date, no stats | L48: Keep the H1 and definition, rewrite the BDR landing-page example and the 'Where does Mutiny fit' section around the sales assistant (runs on triggers after calls: follow-ups, CRM updates, deal rooms). Add an FAQ block and a date. | M48: the agentic AI platform for buyer experiences, personalized landing page, microsite, or outreach asset for a named target account, bought jointly by marketing and sales teams running ABM, send each prospect a personalized landing page | O48: Y | P48: Y | Q48: N | R48: N | S48: N | T48: Y | U48: Y | V48: Y | X48: Not started | Y48: https://www.mutinyhq.com/blog/what-is-agentic-ai-in-sales
A49: /blog/what-is-an-ai-sales-tool | B49: blog | C49: P1 | D49: rewrite | E49: legacy | F49: 3 | G49: ASA (AI Sales Assistants), SE (Sales Enablement) | H49: 1 | I49: 1 | J49: What is an AI sales tool? (H1 rendered twice) | K49: Defines Mutiny as website/account personalization (legacy) on a core definitional page • H1 duplicated • Says '12 leading tools ... six workflow categories' but table has 13 tools in 7 categories • 'See the best AI sales tools in 2026' and 'see the pillar guide' are unlinked in body • 'Only widely-adopted AI sales tool rebuilt from the ground up' unverifiable | L49: Keep the URL and question H1 but rewrite: remove 'personalizes the website' and the 'Account personalization' category, list Mutiny under a 'Sales assistant' category, link the pillar inline, add an FAQ block and a date, and fix the duplicate H1. | M49: leading platform in the buyer-facing account personalization category, personalizes the website and outreach experience for named target accounts, Account personalization (buyer-facing): Mutiny, bought jointly by marketing and sales teams running ABM | O49: Y | P49: Y | Q49: N | R49: N | S49: N | T49: N | U49: Y | V49: Y | X49: Not started | Y49: https://www.mutinyhq.com/blog/what-is-an-ai-sales-tool
A50: /blueprints/case-study-round-up | B50: blueprint | C50: P1 | D50: rewrite | E50: current | F50: 1 | G50: SE (Sales Enablement) | H50: 1 | I50: 0 | J50: Case Study Round Up | K50: Entire body is the Pricing Proposal blueprint copy ('A pricing proposal is a buyer-facing document...'), duplicate of /blueprints/pricing-proposal; only the bottom H1 and tagline are about case study round-ups • FAQ says Enterprise 'starting at $30k' (pricing page: $40,000) • Descriptor 'GTM agent...'; unsourced 4.5x/100% stat • Title 'Mutiny'; generic meta | L50: Replace the copied body with real round-up content. Suggested H1: 'What is a case study round-up page?' First sentence: 'A case study round-up is one page that curates the three to five customer stories most relevant to a buyer's industry, persona or use case, so a champion can forward proof in a single link.' Fix pricing and descriptor, unique title/meta. | N50: July 15, 2026 | O50: N | P50: N | Q50: N | R50: N | S50: N | T50: Y | U50: N | V50: Y | X50: Not started | Y50: https://www.mutinyhq.com/blueprints/case-study-round-up
...
